[0;34m[INFO][0m === 5.3 缺陷工作流测试脚本启动 ===
[0;34m[INFO][0m 时间戳: 20250828_214147
[0;34m[INFO][0m 日志文件: /Users/ruicheng/Documents/GitHub/WorkflowBench/logs/test_5_3_custom_20250828_214147.log
[0;34m[INFO][0m 检查环境和依赖文件...
[0;32m[SUCCESS][0m 所有必需文件检查完成
[0;34m[INFO][0m 获取用户选择...
[0;34m[INFO][0m 用户选择的缺陷类型: flawed_sequence_disorder
[0;34m[INFO][0m 选择开源模型进行测试
[0;34m[INFO][0m 开始执行 5.3 缺陷工作流测试
[0;34m[INFO][0m 总测试数: 1
[0;34m[INFO][0m 模型配置: opensource
[0;34m[INFO][0m 并发配置: 50 workers, 10 processes
[0;34m[INFO][0m 存储配置: JSON + ResultCollector
[0;34m[INFO][0m 🚀 开始测试 - 缺陷类型: flawed_sequence_disorder
[0;34m[INFO][0m 执行命令: USE_RESULT_COLLECTOR=true STORAGE_FORMAT=json python3 ./ultra_parallel_runner.py --test-name '5.3_flawed_flawed_sequence_disorder' --prompt-type 'flawed_sequence_disorder' --difficulty easy --tool-success-rate 0.8 --max-parallel-processes 10 --custom-workers 50 --opensource-models > '/Users/ruicheng/Documents/GitHub/WorkflowBench/logs/ultra_parallel_5_3_flawed_sequence_disorder_20250828_214147.log' 2>&1
[0;31m[ERROR][0m ❌ 测试失败: flawed_sequence_disorder
[0;31m[ERROR][0m 检查日志: /Users/ruicheng/Documents/GitHub/WorkflowBench/logs/ultra_parallel_5_3_flawed_sequence_disorder_20250828_214147.log
[0;31m[ERROR][0m ❌ 失败: flawed_sequence_disorder
[1;33m[WARNING][0m 部分测试失败，请检查日志
