[0;34m[INFO][0m ✅ 已激活conda环境: /Users/ruicheng/miniconda3/bin/python
[0;34m[INFO][0m === 5.3 缺陷工作流测试脚本启动 ===
[0;34m[INFO][0m 时间戳: 20250828_221510
[0;34m[INFO][0m 日志文件: /Users/ruicheng/Documents/GitHub/WorkflowBench/logs/test_5_3_custom_20250828_221510.log
[0;34m[INFO][0m 检查环境和依赖文件...
[0;32m[SUCCESS][0m 所有必需文件检查完成
[0;34m[INFO][0m 获取用户选择...
[0;34m[INFO][0m 用户选择的缺陷类型: flawed_sequence_disorder
[0;34m[INFO][0m 选择开源模型进行测试
[0;34m[INFO][0m 开始执行 5.3 缺陷工作流测试
[0;34m[INFO][0m 缺陷类型数: 1
[0;34m[INFO][0m 测试模型数: 8
[0;34m[INFO][0m 总测试组合: 8
[0;34m[INFO][0m 模型配置: opensource
[0;34m[INFO][0m 并发配置: 50 workers, 10 processes
[0;34m[INFO][0m 存储配置: JSON + ResultCollector
[0;34m[INFO][0m 🚀 开始测试 - 缺陷类型: flawed_sequence_disorder
[0;34m[INFO][0m 进度: 1/8 - 测试模型: DeepSeek-V3-0324
[0;34m[INFO][0m 🚀 开始测试 - 模型: DeepSeek-V3-0324, 缺陷类型: flawed_sequence_disorder
[0;34m[INFO][0m 执行命令: USE_RESULT_COLLECTOR=true STORAGE_FORMAT=json python3 ./ultra_parallel_runner.py --model 'DeepSeek-V3-0324' --prompt-types 'flawed_sequence_disorder' --difficulty easy --tool-success-rate 0.8 --max-workers 50 > '/Users/ruicheng/Documents/GitHub/WorkflowBench/logs/ultra_parallel_DeepSeek_V3_0324_flawed_sequence_disorder_20250828_221510.log' 2>&1
[0;31m[ERROR][0m ❌ 模型 DeepSeek-V3-0324 测试失败
[0;31m[ERROR][0m 检查日志: /Users/ruicheng/Documents/GitHub/WorkflowBench/logs/ultra_parallel_DeepSeek_V3_0324_flawed_sequence_disorder_20250828_221510.log
[0;34m[INFO][0m 等待 3 秒后测试下一个模型...
[1;33m[WARNING][0m 接收到中断信号，正在清理...
[0;34m[INFO][0m 清理完成
